Workbook

Sheet 20in Casing with 50 bbl
B3: GASKICK | E3: Well Name: | F3: JDS-21-01
B4: Version 1.2 October '96 | E4: Rig Type: | F4: TBA
E5: Date: | F5: 44487
E6: Drilling Engineer: | F6: JDS-21
B8: Spread sheet to calculate required formation strength at casing shoe,
B9: assuming a specified gas kick volume and a known formation pressure.
B11: A. INPUT: | AJ11: Wellhead | BF11: Wellhead
B12: Total vertical depth (ft below derrick floor) | F12: TVD= | G12: =AK23 -> 5300 | H12: feet | AJ12: 5000 psi | BF12: 3000 psi
B13: Vertical depth of casing shoe (ft bdf) | F13: TVC= | G13: =AG16 -> 2300 | H13: feet | BG13: =G14-BG19 -> 2722.08
B14: Pore pressure at section TD | F14: PP= | G14: =11.8*0.052*G12 -> 3252.08 | I14: psi
B15: Mud weight at section TD | F15: MW= | G15: =12.3*0.052 -> 0.6396 | I15: psi/ft = | J15: =G15*19.25 -> 12.3123 | K15: ppg | L15: ppg
I16: Overbalance = | J16: =G15*G12-G14 -> 137.8 | L16: psi | AG16: 2300 | AO16: 20" Casing | AS16: FG = 13.3 ppg | BC16: =AC13 -> 0 | BK16: 20" Casing
B17: Inclination at casing shoe | F17: INC shoe= | G17: 0 | I17: deg
B18: Inclination at section TD | F18: INC td = | G18: 0 | I18: deg | BH18: 0.1 psi/ft
AN19: 17-1/2" hole | BG19: =0.1*5300 -> 530 | BJ19: 17-1/2" hole
B20: Hole size | F20: ID hole= | G20: 17.5 | I20: inches
B21: Drillpipe OD | F21: OD dp = | G21: 5 | I21: inches
B22: Drill Collar Lenght | F22: L dc = | G22: 120 | I22: feet
B23: Drill Collar OD | F23: OD dc = | G23: 8.5 | I23: inches | AK23: 5300 | AN23: Total vertical depth (ft below derrick floor) | BF23: 5300 ft | BG23: 3252 psi
B25: Kick volume | F25: KV= | G25: 50 | I25: bbl | J25: =IF(G34<=G14,"Well flowing","")
B26: Gas influx gradient at TD | F26: GG= | G26: 0.1 | I26: psi/ft | J26: =IF(G34<=G14,"@ shut-in!","")
F27: =IF(G33>G12-G13," VKH si >TVD-TVC","") | J27: =IF(G34<=G14,"BHP<PP","")
B28: B. OUTPUT:
B29: Capacities: | D29: open hole/drillpipe | F29: C dp= | G29: =(G20^2-G21^2)/1029.46 -> 0.27320148 | I29: bbl/ft
D30: open hole/drill collar | F30: C dc= | G30: =(G20^2-G23^2)/1029.46 -> 0.22730363 | I30: bbl/ft
D31: open hole length ah | F31: OH ah= | G31: =(G12-G13)/COS((G18+G17)/2*3.14159/180) -> 3000 | I31: ft
B32: Vertical Kick Height:
C33: @ TD shutting in well | F33: VKH si = | G33: =COS(G18*3.14159/180)*IF((G25/G30)<G22,G25/G30,G22+(G25-G30*G22)/G29) -> 203.17511 | I33: feet | K33: ppg
C34: BHP when shuting in well | F34: BHP si = | G34: =IF(G14<G33*G26+(G12-G33)*G15,G33*G26+(G12-G33)*G15,G14) -> 3280.2467 | I34: psi
B35: top gas | C35: @ csg shoe without expansion | F35: VKH shoe= | G35: =COS(G17*3.14159/180)*IF(G22>G31,IF(G25/G30<G22,G25/G30,G22+(G25-G30*G22)/G29),IF(G25/G29<G31-G22,G25/G29,IF(G25<(G31-G22)*G29+G22*G30,G31-G22+(G25-(G31-G22)*G29)/G30,G22+(G25-G22*G30)/G29))) -> 183.01511 | I35: feet
C36: expanded kick volume @ shoe | F36: KV exp = | G36: =G25*(G34-G26*G33)/G41 -> 102.23587 | I36: bbl
B37: top gas | C37: @ csg shoe and expanded | F37: VKH exp = | G37: =COS(G17*3.14159/180)*IF(G22>G31,IF(G36/G30<G22,G36/G30,G22+(G36-G30*G22)/G29),IF(G36/G29<G31-G22,G36/G29,IF(G36<(G31-G22)*G29+G22*G30,G31-G22+(G36-(G31-G22)*G29)/G30,G22+(G36-G22*G30)/G29))) -> 374.2142 | I37: feet
B39: Pressure at casing shoe:
D40: shutting in well | F40: PCS si = | G40: =IF(G33<G12-G13,G34-G33*G26-(G12-G13-G33)*G15,G34-(G12-G13)*G26) -> 1471.08 | I40: psi
D41: with top gas @ csg shoe | F41: PCS exp= | G41: =0.5*(IF((G26*G35+G15*(G12-G35))<G14,G14,G26*G35+G15*(G12-G35))-(G12-G13)*G15-G26*IF(+(G12-G13)>G35,G35,G12-G13))+((0.5*(IF((G26*G35+G15*(G12-G35))<G14,G14,G26*G35+G15*(G12-G35))-(G12-G13)*G15-G26*IF(+(G12-G13)>G35,G35,G12-G13)))^2+((IF((G26*G35+G15*(G12-G35))<G14,G14,G26*G35+G15*(G12-G35))-G26*IF(+(G12-G13)>G35,G35,G12-G13))*G15*IF(+(G12-G13)>G35,G35,G12-G13)))^0.5 -> 1594.3177 | I41: psi
B43: Required FSG @ csg shoe to shut-in well | F43: FSG si = | G43: =1/G13*(IF((G26*G33+G15*(G12-G33))<G14,G14,G26*G33+G15*(G12-G33))-IF(G33>(G12-G13),G12-G13,G33)*G26-(G12-G13-IF(G33>(G12-G13),G12-G13,G33))*G15) -> 0.6396 | I43: psi/ft = | J43: =G43*19.25 -> 12.3123 | L43: ppg
B44: Required FSG with top gas @ csg shoe | F44: FSG exp= | G44: =IF(G13=0,"XXXX",G41/G13) -> 0.69318159 | I44: psi/ft = | J44: =IF(G13=0,"XXXX",G44*19.25) -> 13.343746 | K44: ppg | L44: ppg | N44: FG at 2300 13.3 ppg
G45: =IF(G15>G44,"Warning! MW > FSG","")
G46: =IF(G43>G44,"Warning! FSG si > FSG exp","")
B48: C. STANDARDS & QUALIFICATIONS:
...

Sheet 13-38 Ver with 40 bbl
B3: GASKICK | E3: Well Name: | F3: ='20in Casing with 50 bbl'!F3 -> JDS-21-01
B4: Version 1.2 October '96 | E4: Rig Type: | F4: ='20in Casing with 50 bbl'!F4 -> TBA
E5: Date: | F5: ='20in Casing with 50 bbl'!F5 -> 44487
E6: Drilling Engineer: | F6: ='20in Casing with 50 bbl'!F6 -> JDS-21
B8: Spread sheet to calculate required formation strength at casing shoe,
B9: assuming a specified gas kick volume and a known formation pressure.
B11: A. INPUT:
B12: Total vertical depth (ft below derrick floor) | F12: TVD= | G12: 10000 | H12: feet
B13: Vertical depth of casing shoe (ft bdf) | F13: TVC= | G13: 5300 | H13: feet
B14: Pore pressure at section TD | F14: PP= | G14: =16.2*0.052*G12 -> 8424 | I14: psi
B15: Mud weight at section TD | F15: MW= | G15: =16.7*0.052 -> 0.8684 | I15: psi/ft = | J15: =G15*19.25 -> 16.7167 | K15: ppg | L15: ppg
I16: Overbalance = | J16: =G15*G12-G14 -> 260 | L16: psi | AG16: =G13 -> 5300 | AO16: 13-3/8" Casing
B17: Inclination at casing shoe | F17: INC shoe= | G17: 0 | I17: deg
B18: Inclination at section TD | F18: INC td = | G18: 0 | I18: deg
AN19: 12-1/4" hole
B20: Hole size | F20: ID hole= | G20: 12.25 | I20: inches
B21: Drillpipe OD | F21: OD dp = | G21: 5 | I21: inches
B22: Drill Collar Lenght | F22: L dc = | G22: 120 | I22: feet
B23: Drill Collar OD | F23: OD dc = | G23: 8.5 | I23: inches | AK23: 10000 | AN23: Total vertical depth (ft below derrick floor)
B25: Kick volume | F25: KV= | G25: 40 | I25: bbl | J25: =IF(G34<=G14,"Well flowing","") -> Well flowing
B26: Gas influx gradient at TD | F26: GG= | G26: 0.1 | I26: psi/ft | J26: =IF(G34<=G14,"@ shut-in!","") -> @ shut-in!
F27: =IF(G33>G12-G13," VKH si >TVD-TVC","") | J27: =IF(G34<=G14,"BHP<PP","") -> BHP<PP
B28: B. OUTPUT:
B29: Capacities: | D29: open hole/drillpipe | F29: C dp= | G29: =(G20^2-G21^2)/1029.46 -> 0.12148359 | I29: bbl/ft
D30: open hole/drill collar | F30: C dc= | G30: =(G20^2-G23^2)/1029.46 -> 0.075585744 | I30: bbl/ft
D31: open hole length ah | F31: OH ah= | G31: =(G12-G13)/COS((G18+G17)/2*3.14159/180) -> 4700 | I31: ft
B32: Vertical Kick Height:
C33: @ TD shutting in well | F33: VKH si = | G33: =COS(G18*3.14159/180)*IF((G25/G30)<G22,G25/G30,G22+(G25-G30*G22)/G29) -> 374.5999 | I33: feet | K33: ppg
C34: BHP when shuting in well | F34: BHP si = | G34: =IF(G14<G33*G26+(G12-G33)*G15,G33*G26+(G12-G33)*G15,G14) -> 8424 | I34: psi
B35: top gas | C35: @ csg shoe without expansion | F35: VKH shoe= | G35: =COS(G17*3.14159/180)*IF(G22>G31,IF(G25/G30<G22,G25/G30,G22+(G25-G30*G22)/G29),IF(G25/G29<G31-G22,G25/G29,IF(G25<(G31-G22)*G29+G22*G30,G31-G22+(G25-(G31-G22)*G29)/G30,G22+(G25-G22*G30)/G29))) -> 329.26257 | I35: feet
C36: expanded kick volume @ shoe | F36: KV exp = | G36: =G25*(G34-G26*G33)/G41 -> 69.666244 | I36: bbl
B37: top gas | C37: @ csg shoe and expanded | F37: VKH exp = | G37: =COS(G17*3.14159/180)*IF(G22>G31,IF(G36/G30<G22,G36/G30,G22+(G36-G30*G22)/G29),IF(G36/G29<G31-G22,G36/G29,IF(G36<(G31-G22)*G29+G22*G30,G31-G22+(G36-(G31-G22)*G29)/G30,G22+(G36-G22*G30)/G29))) -> 573.46216 | I37: feet
B39: Pressure at casing shoe:
D40: shutting in well | F40: PCS si = | G40: =IF(G33<G12-G13,G34-G33*G26-(G12-G13-G33)*G15,G34-(G12-G13)*G26) -> 4630.3626 | I40: psi
D41: with top gas @ csg shoe | F41: PCS exp= | G41: =0.5*(IF((G26*G35+G15*(G12-G35))<G14,G14,G26*G35+G15*(G12-G35))-(G12-G13)*G15-G26*IF(+(G12-G13)>G35,G35,G12-G13))+((0.5*(IF((G26*G35+G15*(G12-G35))<G14,G14,G26*G35+G15*(G12-G35))-(G12-G13)*G15-G26*IF(+(G12-G13)>G35,G35,G12-G13)))^2+((IF((G26*G35+G15*(G12-G35))<G14,G14,G26*G35+G15*(G12-G35))-G26*IF(+(G12-G13)>G35,G35,G12-G13))*G15*IF(+(G12-G13)>G35,G35,G12-G13)))^0.5 -> 4815.2675 | I41: psi
B43: Required FSG @ csg shoe to shut-in well | F43: FSG si = | G43: =1/G13*(IF((G26*G33+G15*(G12-G33))<G14,G14,G26*G33+G15*(G12-G33))-IF(G33>(G12-G13),G12-G13,G33)*G26-(G12-G13-IF(G33>(G12-G13),G12-G13,G33))*G15) -> 0.87365331 | I43: psi/ft = | J43: =G43*19.25 -> 16.817826 | L43: ppg
B44: Required FSG with top gas @ csg shoe | F44: FSG exp= | G44: =IF(G13=0,"XXXX",G41/G13) -> 0.90854103 | I44: psi/ft = | J44: =IF(G13=0,"XXXX",G44*19.25) -> 17.489415 | K44: ppg | L44: ppg
G45: =IF(G15>G44,"Warning! MW > FSG","")
G46: =IF(G43>G44,"Warning! FSG si > FSG exp","")
B48: C. STANDARDS & QUALIFICATIONS:
...

Sheet 9-58 Ver with 40 bbl
B3: GASKICK | E3: Well Name: | F3: ='20in Casing with 50 bbl'!F3 -> JDS-21-01
B4: Version 1.2 October '96 | E4: Rig Type: | F4: ='20in Casing with 50 bbl'!F4 -> TBA
E5: Date: | F5: ='20in Casing with 50 bbl'!F5 -> 44487
E6: Drilling Engineer: | F6: ='20in Casing with 50 bbl'!F6 -> JDS-21
B8: Spread sheet to calculate required formation strength at casing shoe,
B9: assuming a specified gas kick volume and a known formation pressure.
B11: A. INPUT:
B12: Total vertical depth (ft below derrick floor) | F12: TVD= | G12: 12000 | H12: feet
B13: Vertical depth of casing shoe (ft bdf) | F13: TVC= | G13: 10000 | H13: feet
B14: Pore pressure at section TD | F14: PP= | G14: =9*0.052*G12 -> 5616 | I14: psi
B15: Mud weight at section TD | F15: MW= | G15: =16.7*0.052 -> 0.8684 | I15: psi/ft = | J15: =G15*19.25 -> 16.7167 | K15: ppg | L15: ppg
I16: Overbalance = | J16: =G15*G12-G14 -> 4804.8 | L16: psi | AF16: 10000 | AN16: 9-5/8" Casing
B17: Inclination at casing shoe | F17: INC shoe= | G17: 0 | I17: deg
B18: Inclination at section TD | F18: INC td = | G18: 0 | I18: deg
AM19: 8.5" hole
B20: Hole size | F20: ID hole= | G20: 8.5 | I20: inches
B21: Drillpipe OD | F21: OD dp = | G21: 5 | I21: inches
B22: Drill Collar Lenght | F22: L dc = | G22: 120 | I22: feet
B23: Drill Collar OD | F23: OD dc = | G23: 6.5 | I23: inches | AJ23: 12000 | AM23: Total vertical depth (ft below derrick floor)
B25: Kick volume | F25: KV= | G25: 40 | I25: bbl | J25: =IF(G34<=G14,"Well flowing","")
B26: Gas influx gradient at TD | F26: GG= | G26: 0.1 | I26: psi/ft | J26: =IF(G34<=G14,"@ shut-in!","")
F27: =IF(G33>G12-G13," VKH si >TVD-TVC","") | J27: =IF(G34<=G14,"BHP<PP","")
B28: B. OUTPUT:
B29: Capacities: | D29: open hole/drillpipe | F29: C dp= | G29: =(G20^2-G21^2)/1029.46 -> 0.045897849 | I29: bbl/ft
D30: open hole/drill collar | F30: C dc= | G30: =(G20^2-G23^2)/1029.46 -> 0.029141492 | I30: bbl/ft
D31: open hole length ah | F31: OH ah= | G31: =(G12-G13)/COS((G18+G17)/2*3.14159/180) -> 2000 | I31: ft
B32: Vertical Kick Height:
C33: @ TD shutting in well | F33: VKH si = | G33: =COS(G18*3.14159/180)*IF((G25/G30)<G22,G25/G30,G22+(G25-G30*G22)/G29) -> 915.31005 | I33: feet | K33: ppg
C34: BHP when shuting in well | F34: BHP si = | G34: =IF(G14<G33*G26+(G12-G33)*G15,G33*G26+(G12-G33)*G15,G14) -> 9717.4758 | I34: psi
B35: top gas | C35: @ csg shoe without expansion | F35: VKH shoe= | G35: =COS(G17*3.14159/180)*IF(G22>G31,IF(G25/G30<G22,G25/G30,G22+(G25-G30*G22)/G29),IF(G25/G29<G31-G22,G25/G29,IF(G25<(G31-G22)*G29+G22*G30,G31-G22+(G25-(G31-G22)*G29)/G30,G22+(G25-G22*G30)/G29))) -> 871.50053 | I35: feet
C36: expanded kick volume @ shoe | F36: KV exp = | G36: =G25*(G34-G26*G33)/G41 -> 43.944471 | I36: bbl
B37: top gas | C37: @ csg shoe and expanded | F37: VKH exp = | G37: =COS(G17*3.14159/180)*IF(G22>G31,IF(G36/G30<G22,G36/G30,G22+(G36-G30*G22)/G29),IF(G36/G29<G31-G22,G36/G29,IF(G36<(G31-G22)*G29+G22*G30,G31-G22+(G36-(G31-G22)*G29)/G30,G22+(G36-G22*G30)/G29))) -> 957.44075 | I37: feet
B39: Pressure at casing shoe:
D40: shutting in well | F40: PCS si = | G40: =IF(G33<G12-G13,G34-G33*G26-(G12-G13-G33)*G15,G34-(G12-G13)*G26) -> 8684 | I40: psi | Y40: MW 16.7
D41: with top gas @ csg shoe | F41: PCS exp= | G41: =0.5*(IF((G26*G35+G15*(G12-G35))<G14,G14,G26*G35+G15*(G12-G35))-(G12-G13)*G15-G26*IF(+(G12-G13)>G35,G35,G12-G13))+((0.5*(IF((G26*G35+G15*(G12-G35))<G14,G14,G26*G35+G15*(G12-G35))-(G12-G13)*G15-G26*IF(+(G12-G13)>G35,G35,G12-G13)))^2+((IF((G26*G35+G15*(G12-G35))<G14,G14,G26*G35+G15*(G12-G35))-G26*IF(+(G12-G13)>G35,G35,G12-G13))*G15*IF(+(G12-G13)>G35,G35,G12-G13)))^0.5 -> 8761.9166 | I41: psi | Y41: =(16.9-16.7)*0.052*10000 -> 104
B43: Required FSG @ csg shoe to shut-in well | F43: FSG si = | G43: =1/G13*(IF((G26*G33+G15*(G12-G33))<G14,G14,G26*G33+G15*(G12-G33))-IF(G33>(G12-G13),G12-G13,G33)*G26-(G12-G13-IF(G33>(G12-G13),G12-G13,G33))*G15) -> 0.8684 | I43: psi/ft = | J43: =G43*19.25 -> 16.7167 | L43: ppg
B44: Required FSG with top gas @ csg shoe | F44: FSG exp= | G44: =IF(G13=0,"XXXX",G41/G13) -> 0.87619166 | I44: psi/ft = | J44: =IF(G13=0,"XXXX",G44*19.25) -> 16.866689 | K44: ppg | L44: ppg
G45: =IF(G15>G44,"Warning! MW > FSG","")
G46: =IF(G43>G44,"Warning! FSG si > FSG exp","")
B48: C. STANDARDS & QUALIFICATIONS:
...

Sheet 7 in Casing
B3: GASKICK | E3: Well Name: | F3: ='20in Casing with 50 bbl'!F3 -> JDS-21-01
B4: Version 1.2 October '96 | E4: Rig Type: | F4: ='20in Casing with 50 bbl'!F4 -> TBA
E5: Date: | F5: ='20in Casing with 50 bbl'!F5 -> 44487
E6: Drilling Engineer: | F6: ='20in Casing with 50 bbl'!F6 -> JDS-21
B8: Spread sheet to calculate required formation strength at casing shoe,
B9: assuming a specified gas kick volume and a known formation pressure.
B11: A. INPUT:
B12: Total vertical depth (ft below derrick floor) | F12: TVD= | G12: =I12*3.281 -> 4262.019 | H12: feet | I12: =1299 -> 1299
B13: Vertical depth of casing shoe (ft bdf) | F13: TVC= | G13: =I13*3.281 -> 1906.261 | H13: feet | I13: =581 -> 581
B14: Pore pressure at section TD | F14: PP= | G14: =8.5*0.052*G12 -> 1883.8124 | I14: psi
B15: Mud weight at section TD | F15: MW= | G15: =10.5*0.052 -> 0.546 | I15: psi/ft = | J15: =G15*19.25 -> 10.5105 | K15: ppg | L15: ppg
I16: Overbalance = | J16: =G15*G12-G14 -> 443.24998 | L16: psi
B17: Inclination at casing shoe | F17: INC shoe= | G17: 0 | I17: deg
B18: Inclination at section TD | F18: INC td = | G18: 0 | I18: deg
B20: Hole size | F20: ID hole= | G20: 8.5 | I20: inches
B21: Drillpipe OD | F21: OD dp = | G21: 5 | I21: inches
B22: Drill Collar Lenght | F22: L dc = | G22: 120 | I22: feet
B23: Drill Collar OD | F23: OD dc = | G23: 6.5 | I23: inches
B25: Kick volume | F25: KV= | G25: 40 | I25: bbl | J25: =IF(G34<=G14,"Well flowing","")
B26: Gas influx gradient at TD | F26: GG= | G26: 0.1 | I26: psi/ft | J26: =IF(G34<=G14,"@ shut-in!","")
F27: =IF(G33>G12-G13," VKH si >TVD-TVC","") | J27: =IF(G34<=G14,"BHP<PP","")
B28: B. OUTPUT:
B29: Capacities: | D29: open hole/drillpipe | F29: C dp= | G29: =(G20^2-G21^2)/1029.46 -> 0.045897849 | I29: bbl/ft
D30: open hole/drill collar | F30: C dc= | G30: =(G20^2-G23^2)/1029.46 -> 0.029141492 | I30: bbl/ft
D31: open hole length ah | F31: OH ah= | G31: =(G12-G13)/COS((G18+G17)/2*3.14159/180) -> 2355.758 | I31: ft
B32: Vertical Kick Height:
C33: @ TD shutting in well | F33: VKH si = | G33: =COS(G18*3.14159/180)*IF((G25/G30)<G22,G25/G30,G22+(G25-G30*G22)/G29) -> 915.31005 | I33: feet | K33: ppg
C34: BHP when shuting in well | F34: BHP si = | G34: =IF(G14<G33*G26+(G12-G33)*G15,G33*G26+(G12-G33)*G15,G14) -> 1918.8341 | I34: psi
B35: top gas | C35: @ csg shoe without expansion | F35: VKH shoe= | G35: =COS(G17*3.14159/180)*IF(G22>G31,IF(G25/G30<G22,G25/G30,G22+(G25-G30*G22)/G29),IF(G25/G29<G31-G22,G25/G29,IF(G25<(G31-G22)*G29+G22*G30,G31-G22+(G25-(G31-G22)*G29)/G30,G22+(G25-G22*G30)/G29))) -> 871.50053 | I35: feet
C36: expanded kick volume @ shoe | F36: KV exp = | G36: =G25*(G34-G26*G33)/G41 -> 57.88856 | I36: bbl
B37: top gas | C37: @ csg shoe and expanded | F37: VKH exp = | G37: =COS(G17*3.14159/180)*IF(G22>G31,IF(G36/G30<G22,G36/G30,G22+(G36-G30*G22)/G29),IF(G36/G29<G31-G22,G36/G29,IF(G36<(G31-G22)*G29+G22*G30,G31-G22+(G36-(G31-G22)*G29)/G30,G22+(G36-G22*G30)/G29))) -> 1261.2478 | I37: feet
B39: Pressure at casing shoe:
D40: shutting in well | F40: PCS si = | G40: =IF(G33<G12-G13,G34-G33*G26-(G12-G13-G33)*G15,G34-(G12-G13)*G26) -> 1040.8185 | I40: psi
D41: with top gas @ csg shoe | F41: PCS exp= | G41: =0.5*(IF((G26*G35+G15*(G12-G35))<G14,G14,G26*G35+G15*(G12-G35))-(G12-G13)*G15-G26*IF(+(G12-G13)>G35,G35,G12-G13))+((0.5*(IF((G26*G35+G15*(G12-G35))<G14,G14,G26*G35+G15*(G12-G35))-(G12-G13)*G15-G26*IF(+(G12-G13)>G35,G35,G12-G13)))^2+((IF((G26*G35+G15*(G12-G35))<G14,G14,G26*G35+G15*(G12-G35))-G26*IF(+(G12-G13)>G35,G35,G12-G13))*G15*IF(+(G12-G13)>G35,G35,G12-G13)))^0.5 -> 1262.635 | I41: psi
B43: Required FSG @ csg shoe to shut-in well | F43: FSG si = | G43: =1/G13*(IF((G26*G33+G15*(G12-G33))<G14,G14,G26*G33+G15*(G12-G33))-IF(G33>(G12-G13),G12-G13,G33)*G26-(G12-G13-IF(G33>(G12-G13),G12-G13,G33))*G15) -> 0.546 | I43: psi/ft = | J43: =G43*19.25 -> 10.5105 | L43: ppg
B44: Required FSG with top gas @ csg shoe | F44: FSG exp= | G44: =IF(G13=0,"XXXX",G41/G13) -> 0.6623621 | I44: psi/ft = | J44: =IF(G13=0,"XXXX",G44*19.25) -> 12.75047 | K44: ppg | L44: ppg
G45: =IF(G15>G44,"Warning! MW > FSG","")
G46: =IF(G43>G44,"Warning! FSG si > FSG exp","")
B48: C. STANDARDS & QUALIFICATIONS:
B50: 1. Refer to the PCSB Well Design Manual for kick tolerance standards.
...

Sheet 13-38 Ver with 40 bbl Deep
B3: GASKICK | E3: Well Name: | F3: ='20in Casing with 50 bbl'!F3 -> JDS-21-01
B4: Version 1.2 October '96 | E4: Rig Type: | F4: ='20in Casing with 50 bbl'!F4 -> TBA
E5: Date: | F5: ='20in Casing with 50 bbl'!F5 -> 44487
E6: Drilling Engineer: | F6: ='20in Casing with 50 bbl'!F6 -> JDS-21
B8: Spread sheet to calculate required formation strength at casing shoe,
B9: assuming a specified gas kick volume and a known formation pressure.
B11: A. INPUT:
B12: Total vertical depth (ft below derrick floor) | F12: TVD= | G12: 12000 | H12: feet
B13: Vertical depth of casing shoe (ft bdf) | F13: TVC= | G13: 6500 | H13: feet
B14: Pore pressure at section TD | F14: PP= | G14: =16.2*0.052*10500 -> 8845.2 | I14: psi
B15: Mud weight at section TD | F15: MW= | G15: =16.7*0.052 -> 0.8684 | I15: psi/ft = | J15: =G15*19.25 -> 16.7167 | K15: ppg | L15: ppg
I16: Overbalance = | J16: =G15*G12-G14 -> 1575.6 | L16: psi | AG16: =G13 -> 6500 | AO16: 13-3/8" Casing | AT16: FG: 18 ppg
B17: Inclination at casing shoe | F17: INC shoe= | G17: 0 | I17: deg
B18: Inclination at section TD | F18: INC td = | G18: 0 | I18: deg
AN19: 12-1/4" hole
B20: Hole size | F20: ID hole= | G20: 12.25 | I20: inches
B21: Drillpipe OD | F21: OD dp = | G21: 5 | I21: inches
B22: Drill Collar Lenght | F22: L dc = | G22: 120 | I22: feet
B23: Drill Collar OD | F23: OD dc = | G23: 8.5 | I23: inches | AK23: 10000 | AN23: Total vertical depth (ft below derrick floor)
B25: Kick volume | F25: KV= | G25: 40 | I25: bbl | J25: =IF(G34<=G14,"Well flowing","")
B26: Gas influx gradient at TD | F26: GG= | G26: 0.1 | I26: psi/ft | J26: =IF(G34<=G14,"@ shut-in!","")
F27: =IF(G33>G12-G13," VKH si >TVD-TVC","") | J27: =IF(G34<=G14,"BHP<PP","")
B28: B. OUTPUT:
B29: Capacities: | D29: open hole/drillpipe | F29: C dp= | G29: =(G20^2-G21^2)/1029.46 -> 0.12148359 | I29: bbl/ft
D30: open hole/drill collar | F30: C dc= | G30: =(G20^2-G23^2)/1029.46 -> 0.075585744 | I30: bbl/ft
D31: open hole length ah | F31: OH ah= | G31: =(G12-G13)/COS((G18+G17)/2*3.14159/180) -> 5500 | I31: ft
B32: Vertical Kick Height:
C33: @ TD shutting in well | F33: VKH si = | G33: =COS(G18*3.14159/180)*IF((G25/G30)<G22,G25/G30,G22+(G25-G30*G22)/G29) -> 374.5999 | I33: feet | K33: ppg
C34: BHP when shuting in well | F34: BHP si = | G34: =IF(G14<G33*G26+(G12-G33)*G15,G33*G26+(G12-G33)*G15,G14) -> 10132.957 | I34: psi
B35: top gas | C35: @ csg shoe without expansion | F35: VKH shoe= | G35: =COS(G17*3.14159/180)*IF(G22>G31,IF(G25/G30<G22,G25/G30,G22+(G25-G30*G22)/G29),IF(G25/G29<G31-G22,G25/G29,IF(G25<(G31-G22)*G29+G22*G30,G31-G22+(G25-(G31-G22)*G29)/G30,G22+(G25-G22*G30)/G29))) -> 329.26257 | I35: feet
C36: expanded kick volume @ shoe | F36: KV exp = | G36: =G25*(G34-G26*G33)/G41 -> 68.985201 | I36: bbl
B37: top gas | C37: @ csg shoe and expanded | F37: VKH exp = | G37: =COS(G17*3.14159/180)*IF(G22>G31,IF(G36/G30<G22,G36/G30,G22+(G36-G30*G22)/G29),IF(G36/G29<G31-G22,G36/G29,IF(G36<(G31-G22)*G29+G22*G30,G31-G22+(G36-(G31-G22)*G29)/G30,G22+(G36-G22*G30)/G29))) -> 567.85611 | I37: feet
B39: Pressure at casing shoe:
D40: shutting in well | F40: PCS si = | G40: =IF(G33<G12-G13,G34-G33*G26-(G12-G13-G33)*G15,G34-(G12-G13)*G26) -> 5644.6 | I40: psi
D41: with top gas @ csg shoe | F41: PCS exp= | G41: =0.5*(IF((G26*G35+G15*(G12-G35))<G14,G14,G26*G35+G15*(G12-G35))-(G12-G13)*G15-G26*IF(+(G12-G13)>G35,G35,G12-G13))+((0.5*(IF((G26*G35+G15*(G12-G35))<G14,G14,G26*G35+G15*(G12-G35))-(G12-G13)*G15-G26*IF(+(G12-G13)>G35,G35,G12-G13)))^2+((IF((G26*G35+G15*(G12-G35))<G14,G14,G26*G35+G15*(G12-G35))-G26*IF(+(G12-G13)>G35,G35,G12-G13))*G15*IF(+(G12-G13)>G35,G35,G12-G13)))^0.5 -> 5853.7178 | I41: psi
B43: Required FSG @ csg shoe to shut-in well | F43: FSG si = | G43: =1/G13*(IF((G26*G33+G15*(G12-G33))<G14,G14,G26*G33+G15*(G12-G33))-IF(G33>(G12-G13),G12-G13,G33)*G26-(G12-G13-IF(G33>(G12-G13),G12-G13,G33))*G15) -> 0.8684 | I43: psi/ft = | J43: =G43*19.25 -> 16.7167 | L43: ppg
B44: Required FSG with top gas @ csg shoe | F44: FSG exp= | G44: =IF(G13=0,"XXXX",G41/G13) -> 0.90057196 | I44: psi/ft = | J44: =IF(G13=0,"XXXX",G44*19.25) -> 17.33601 | K44: ppg | L44: ppg
G45: =IF(G15>G44,"Warning! MW > FSG","")
G46: =IF(G43>G44,"Warning! FSG si > FSG exp","")
B48: C. STANDARDS & QUALIFICATIONS:
...
